<?xml version='1.0'?>

<robot name="trackbot" xmlns:xacro="http://www.ros.org/wiki/xacro">

  <link name="base_footprint"></link>
  <xacro:include filename="$(find gcamp_gazebo)/urdf/trackbot.gazebo" />

  <joint name="base_footprint_joint" type="fixed">
    <origin xyz="0 0 0" rpy="0 0 0" />
    <parent link="base_footprint" />
    <child link="base_link" />
  </joint>

  <link name='base_link'>
    <pose frame=''>0 0 0 0 0 0</pose>

    <inertial>
      <origin xyz="0.0 0 0.118" rpy="1.5708 -0 0" />
      <mass value="13.14" />
      <inertia ixx="0.10019" ixy="0.0" ixz="0.0" iyy="0.345043" iyz="0.0" izz="0.302044" />
    </inertial>

    <collision name='base_link_collision'>
      <origin xyz="0.0 0 0.118" rpy="0 -0 0" />
      <geometry>
        <box size="0.50017 0.24093 0.139" />
      </geometry>
    </collision>

    <visual name='base_link_visual'>
      <origin xyz="0.0 0 0.118" rpy="0 -0 0" />
      <geometry>
        <box size="0.50017 0.24093 0.139" />
      </geometry>
    </visual>
  </link>

  <link name="front_left_wheel">
    <inertial>
      <mass value="8.0" />
      <origin xyz="0.0 0 0" rpy=" 0 1.5707 1.5707" />
      <inertia ixx="0.1" ixy="0" ixz="0" iyy="0.1" iyz="0" izz="0.1" />
    </inertial>

    <visual>
      <origin xyz="0.0 0 0" rpy=" 0 1.5707 1.5707" />
      <geometry>
        <cylinder length="0.09728" radius="0.12" />
      </geometry>
    </visual>

    <collision>
      <origin xyz="0.0 0 0" rpy=" 0 1.5707 1.5707" />
      <geometry>
        <cylinder length="0.09728" radius="0.12" />
      </geometry>
    </collision>
  </link>

  <link name="back_left_wheel">
    <inertial>
      <mass value="8.0" />
      <origin xyz="0.0 0 0" rpy=" 0 1.5707 1.5707" />
      <inertia ixx="0.1" ixy="0" ixz="0" iyy="0.1" iyz="0" izz="0.1" />
    </inertial>

    <visual>
      <origin xyz="0.0 0 0" rpy=" 0 1.5707 1.5707" />
      <geometry>
        <cylinder length="0.09728" radius="0.12" />
      </geometry>
    </visual>

    <collision>
      <origin xyz="0.0 0 0" rpy=" 0 1.5707 1.5707" />
      <geometry>
        <cylinder length="0.09728" radius="0.12" />
      </geometry>
    </collision>
  </link>

  <link name="front_right_wheel">
    <inertial>
      <mass value="8.0" />
      <origin xyz="0.0 0 0" rpy=" 0 1.5707 1.5707" />
      <inertia ixx="0.1" ixy="0" ixz="0" iyy="0.1" iyz="0" izz="0.1" />
    </inertial>

    <visual>
      <origin xyz="0.0 0 0" rpy=" 0 1.5707 1.5707" />
      <geometry>
        <cylinder length="0.09728" radius="0.12" />
      </geometry>
    </visual>

    <collision>
      <origin xyz="0.0 0 0" rpy=" 0 1.5707 1.5707" />
      <geometry>
        <cylinder length="0.09728" radius="0.12" />
      </geometry>
    </collision>
  </link>

  <link name="back_right_wheel">
    <inertial>
      <mass value="8.0" />
      <origin xyz="0.0 0 0" rpy=" 0 1.5707 1.5707" />
      <inertia ixx="0.1" ixy="0" ixz="0" iyy="0.1" iyz="0" izz="0.1" />
    </inertial>

    <visual>
      <origin xyz="0.0 0 0" rpy=" 0 1.5707 1.5707" />
      <geometry>
        <cylinder length="0.09728" radius="0.12" />
      </geometry>
    </visual>

    <collision>
      <origin xyz="0.0 0 0" rpy=" 0 1.5707 1.5707" />
      <geometry>
        <cylinder length="0.09728" radius="0.12" />
      </geometry>
    </collision>
  </link>

  <joint type="continuous" name="front_left_wheel_joint">
    <origin xyz="0.15 0.1985 0.01855" rpy="0 0 0" />
    <child link="front_left_wheel" />
    <parent link="base_link" />
    <axis xyz="0 1 0" rpy="0 0 0" />
    <limit effort="10000" velocity="1000" />
    <dynamics damping="1.0" friction="5.0" />
  </joint>

  <joint type="continuous" name="front_right_wheel_joint">
    <origin xyz="0.15 -0.1985 0.01855" rpy="0 0 0" />
    <child link="front_right_wheel" />
    <parent link="base_link" />
    <axis xyz="0 1 0" rpy="0 0 0" />
    <limit effort="10000" velocity="1000" />
    <dynamics damping="1.0" friction="5.0" />
  </joint>

  <joint type="continuous" name="back_left_wheel_joint">
    <origin xyz="-0.15 0.1985 0.01855" rpy="0 0 0" />
    <child link="back_left_wheel" />
    <parent link="base_link" />
    <axis xyz="0 1 0" rpy="0 0 0" />
    <limit effort="10000" velocity="1000" />
    <dynamics damping="1.0" friction="5.0" />
  </joint>

  <joint type="continuous" name="back_right_wheel_joint">
    <origin xyz="-0.15 -0.1985 0.01855" rpy="0 0 0" />
    <child link="back_right_wheel" />
    <parent link="base_link" />
    <axis xyz="0 1 0" rpy="0 0 0" />
    <limit effort="10000" velocity="1000" />
    <dynamics damping="1.0" friction="5.0" />
  </joint>

</robot>